Workbook

Sheet onglet 1
A1: ISO | B1: Country | C1: region | D1: Data source | E1: Sector | F1: Gas | G1: Unit | H1: 2050 | I1: 2049 | J1: 2048 | K1: 2047 | L1: 2046 | M1: 2045 | N1: 2044 | O1: 2043 | P1: 2042 | Q1: 2041 | R1: 2040 | S1: 2039 | T1: 2038 | U1: 2037 | V1: 2036 | W1: 2035 | X1: 2034 | Y1: 2033 | Z1: 2032 | AA1: 2031 | AB1: 2030 | AC1: 2029 | AD1: 2028 | AE1: 2027 | AF1: 2026 | AG1: 2025 | AH1: 2024 | AI1: 2023 | AJ1: 2022 | AK1: 2021 | AL1: 2020 | AM1: 2019 | AN1: 2018 | AO1: 2017 | AP1: 2016 | AQ1: 2015 | AR1: 2014 | AS1: 2013 | AT1: 2012 | AU1: 2011 | AV1: 2010 | AW1: 2009 | AX1: 2008 | AY1: 2007 | AZ1: 2006 | BA1: 2005 | BB1: 2004 | BC1: 2003 | BD1: 2002 | BE1: 2001 | BF1: 2000 | BG1: 1999 | BH1: 1998 | BI1: 1997 | BJ1: 1996 | BK1: 1995 | BL1: 1994 | BM1: 1993 | BN1: 1992 | BO1: 1991 | BP1: 1990 | BQ1: TCAM(2000-2010) | BR1: TCAM(2010-2019)
A2: WORLD | B2: World | C2: =VLOOKUP(historical_emissions[[#This Row],[Country]],'Liste-Pays'!A:B,2,0) -> World | D2: Climate Watch | E2: Total including LUCF | F2: CO2 | G2: MtCO₂e | H2: =I2*(1+$BR2) -> 58576.744 | I2: =J2*(1+$BR2) -> 57930.7 | J2: =K2*(1+$BR2) -> 57291.782 | K2: =L2*(1+$BR2) -> 56659.909 | L2: =M2*(1+$BR2) -> 56035.006 | M2: =N2*(1+$BR2) -> 55416.995 | N2: =O2*(1+$BR2) -> 54805.8 | O2: =P2*(1+$BR2) -> 54201.346 | ... Y2: =Z2*(1+$BR2) -> 48511.595 | Z2: =AA2*(1+$BQ2) -> 47976.56 | AA2: =AB2*(1+$BQ2) -> 46758.546 | AB2: =AC2*(1+$BQ2) -> 45571.455 | AC2: =AD2*(1+$BQ2) -> 44414.501 | AD2: =AE2*(1+$BQ2) -> 43286.919 | AE2: =AF2*(1+$BQ2) -> 42187.964 | AF2: =AG2*(1+$BQ2) -> 41116.91 | AG2: =AH2*(1+$BQ2) -> 40073.046 | ... AI2: =AJ2*(1+$BQ2) -> 38064.151 | AJ2: 37097.79 | AK2: 36764.09 | AL2: 34878.72 | AM2: 36990.83 | AN2: 36804.24 | AO2: 35848.27 | AP2: 35331.65 | AQ2: 34674.54 | AR2: 34821.75 | AS2: 34424.88 | AT2: 33777.75 | AU2: 33401.41 | AV2: 33476.96 | AW2: 31890.67 | AX2: 32004.56 | AY2: 31795.84 | AZ2: 31108.35 | BA2: 29885.52 | BB2: 29047.79 | BC2: 27587.62 | BD2: 26711.12 | BE2: 25975.6 | BF2: 25886 | BG2: 25218.47 | BH2: 25144.99 | BI2: 25536.99 | BJ2: 24427.66 | BK2: 24078.35 | BL2: 23452.62 | BM2: 23307.59 | BN2: 23161.98 | BO2: 23208.89 | BP2: 23052.66 | BQ2: =((AV2/BF2)^(1/(2010-2000)))-1 -> 0.026049012 | BR2: =((AM2/AV2)^(1/(2019-2010)))-1 -> 0.011152014
A3: WORLD | B3: World | C3: =VLOOKUP(historical_emissions[[#This Row],[Country]],'Liste-Pays'!A:B,2,0) -> World | D3: Climate Watch | E3: Energy | F3: CO2 | G3: MtCO₂e | H3: =I3*(1+$BR3) -> 54416.576 | I3: =J3*(1+$BR3) -> 53847.281 | J3: =K3*(1+$BR3) -> 53283.943 | K3: =L3*(1+$BR3) -> 52726.498 | L3: =M3*(1+$BR3) -> 52174.884 | M3: =N3*(1+$BR3) -> 51629.042 | N3: =O3*(1+$BR3) -> 51088.91 | O3: =P3*(1+$BR3) -> 50554.429 | ... Y3: =Z3*(1+$BR3) -> 45507.704 | Z3: =AA3*(1+$BQ3) -> 45031.612 | AA3: =AB3*(1+$BQ3) -> 43832.273 | AB3: =AC3*(1+$BQ3) -> 42664.877 | AC3: =AD3*(1+$BQ3) -> 41528.572 | AD3: =AE3*(1+$BQ3) -> 40422.53 | AE3: =AF3*(1+$BQ3) -> 39345.947 | AF3: =AG3*(1+$BQ3) -> 38298.036 | AG3: =AH3*(1+$BQ3) -> 37278.034 | ... AI3: =AJ3*(1+$BQ3) -> 35318.805 | AJ3: 34378.15 | AK3: 33944.44 | AL3: 32079.31 | AM3: 33905.55 | AN3: 33961.58 | AO3: 33200.14 | AP3: 32672.54 | AQ3: 32652.25 | AR3: 32767.54 | AS3: 32680.89 | AT3: 32084.47 | AU3: 31750.41 | AV3: 30843.52 | AW3: 29048.01 | AX3: 29498.92 | AY3: 29289.41 | AZ3: 28254.61 | BA3: 27407.85 | BB3: 26434.4 | BC3: 25283.1 | BD3: 24212.38 | BE3: 23880.51 | BF3: 23546.64 | BG3: 22857.52 | BH3: 22719.06 | BI3: 22552.84 | BJ3: 22158.58 | BK3: 21689.61 | BL3: 21102.75 | BM3: 20994.79 | BN3: 20873.09 | BO3: 20941.2 | BP3: 20796.98 | BQ3: =((AV3/BF3)^(1/(2010-2000)))-1 -> 0.027362003 | BR3: =((AM3/AV3)^(1/(2019-2010)))-1 -> 0.01057239
A4: CHN | B4: China | C4: =VLOOKUP(historical_emissions[[#This Row],[Country]],'Liste-Pays'!A:B,2,0) -> CHI | D4: Climate Watch | E4: Total including LUCF | F4: CO2 | G4: MtCO₂e | H4: =I4*(1+$BR4) -> 44992.252 | I4: =J4*(1+$BR4) -> 43917.33 | J4: =K4*(1+$BR4) -> 42868.088 | K4: =L4*(1+$BR4) -> 41843.914 | L4: =M4*(1+$BR4) -> 40844.209 | M4: =N4*(1+$BR4) -> 39868.388 | N4: =O4*(1+$BR4) -> 38915.881 | O4: =P4*(1+$BR4) -> 37986.131 | ... Y4: =Z4*(1+$BR4) -> 29826.82 | Z4: =AA4*(1+$BQ4) -> 29114.219 | AA4: =AB4*(1+$BQ4) -> 26338.287 | AB4: =AC4*(1+$BQ4) -> 23827.029 | AC4: =AD4*(1+$BQ4) -> 21555.211 | AD4: =AE4*(1+$BQ4) -> 19500.002 | AE4: =AF4*(1+$BQ4) -> 17640.75 | AF4: =AG4*(1+$BQ4) -> 15958.77 | AG4: =AH4*(1+$BQ4) -> 14437.161 | ... AI4: =AJ4*(1+$BQ4) -> 11815.349 | AJ4: 10688.8 | AK4: 10734.63 | AL4: 10190.85 | AM4: 10077.44 | AN4: 9853.69 | AO4: 9392.5 | AP4: 9181.1 | AQ4: 9111.39 | AR4: 9256.88 | AS4: 9227.79 | AT4: 8794.16 | AU4: 8534.55 | AV4: 8106.51 | AW4: 7348.88 | AX4: 6829.82 | AY4: 6621.3 | AZ4: 6070.7 | BA4: 5465.92 | BB4: 4752.76 | BC4: 4070.73 | BD4: 3443.96 | BE4: 3174.78 | BF4: 2976.17 | BG4: 2802.53 | BH4: 2885.43 | BI4: 2783.35 | BJ4: 2719.94 | BK4: 2738.26 | BL4: 2417.56 | BM4: 2295.62 | BN4: 2068.89 | BO4: 1953.17 | BP4: 1824.64 | BQ4: =((AV4/BF4)^(1/(2010-2000)))-1 -> 0.10539531 | BR4: =((AM4/AV4)^(1/(2019-2010)))-1 -> 0.024476052
A5: CHN | B5: China | C5: =VLOOKUP(historical_emissions[[#This Row],[Country]],'Liste-Pays'!A:B,2,0) -> CHI | D5: Climate Watch | E5: Energy | F5: CO2 | G5: MtCO₂e | H5: =I5*(1+$BR5) -> 43398.968 | I5: =J5*(1+$BR5) -> 42259.953 | J5: =K5*(1+$BR5) -> 41150.832 | K5: =L5*(1+$BR5) -> 40070.82 | L5: =M5*(1+$BR5) -> 39019.154 | M5: =N5*(1+$BR5) -> 37995.088 | N5: =O5*(1+$BR5) -> 36997.899 | O5: =P5*(1+$BR5) -> 36026.882 | ... Y5: =Z5*(1+$BR5) -> 27613.584 | Z5: =AA5*(1+$BQ5) -> 26888.86 | AA5: =AB5*(1+$BQ5) -> 24502.977 | AB5: =AC5*(1+$BQ5) -> 22328.796 | AC5: =AD5*(1+$BQ5) -> 20347.534 | AD5: =AE5*(1+$BQ5) -> 18542.071 | AE5: =AF5*(1+$BQ5) -> 16896.809 | AF5: =AG5*(1+$BQ5) -> 15397.533 | AG5: =AH5*(1+$BQ5) -> 14031.29 | ... AI5: =AJ5*(1+$BQ5) -> 11651.733 | AJ5: 10617.86 | AK5: 10579.99 | AL5: 10010 | AM5: 9919.39 | AN5: 9748.89 | AO5: 9299.81 | AP5: 9100.91 | AQ5: 9113.07 | AR5: 9207.76 | AS5: 9200.27 | AT5: 8799.53 | AU5: 8546.02 | AV5: 7807.85 | AW5: 7105.31 | AX5: 6642.96 | AY5: 6445.15 | AZ5: 5938.66 | BA5: 5384.36 | BB5: 4720.71 | BC5: 4053.2 | BD5: 3496.14 | BE5: 3238.66 | BF5: 3083.16 | BG5: 2925.34 | BH5: 3024.86 | BI5: 2931.18 | BJ5: 2877.57 | BK5: 2904.0 | BL5: 2603.25 | BM5: 2502.6 | BN5: 2295.78 | BO5: 2200.89 | BP5: 2088.85 | BQ5: =((AV5/BF5)^(1/(2010-2000)))-1 -> 0.097371154 | BR5: =((AM5/AV5)^(1/(2019-2010)))-1 -> 0.026952578
A6: WORLD | B6: World | C6: =VLOOKUP(historical_emissions[[#This Row],[Country]],'Liste-Pays'!A:B,2,0) -> World | D6: Climate Watch | E6: Total including LUCF | F6: CH4 | G6: MtCO₂e | H6: =I6*(1+$BR6) -> 11710.383 | I6: =J6*(1+$BR6) -> 11639.901 | J6: =K6*(1+$BR6) -> 11569.844 | K6: =L6*(1+$BR6) -> 11500.208 | L6: =M6*(1+$BR6) -> 11430.991 | M6: =N6*(1+$BR6) -> 11362.191 | N6: =O6*(1+$BR6) -> 11293.805 | O6: =P6*(1+$BR6) -> 11225.83 | ... Y6: =Z6*(1+$BR6) -> 10568.185 | Z6: =AA6*(1+$BQ6) -> 10504.578 | AA6: =AB6*(1+$BQ6) -> 10410.184 | AB6: =AC6*(1+$BQ6) -> 10316.639 | AC6: =AD6*(1+$BQ6) -> 10223.934 | AD6: =AE6*(1+$BQ6) -> 10132.062 | AE6: =AF6*(1+$BQ6) -> 10041.016 | AF6: =AG6*(1+$BQ6) -> 9950.7873 | AG6: =AH6*(1+$BQ6) -> 9861.37 | ... AI6: =AJ6*(1+$BQ6) -> 9684.9385 | AJ6: 9597.91 | AK6: 9508.12 | AL6: 9383.48 | AM6: 9691.82 | AN6: 9560.18 | AO6: 9437.98 | AP6: 9358.45 | AQ6: 9502.89 | AR6: 9489.94 | AS6: 9316.29 | AT6: 9364.63 | AU6: 9316.82 | AV6: 9179.29 | AW6: 9082.66 | AX6: 9068.71 | AY6: 9036.2 | AZ6: 9079.13 | BA6: 8898.31 | BB6: 8835.91 | BC6: 8574.58 | BD6: 8502.58 | BE6: 8337.46 | BF6: 8387.01 | BG6: 8371.45 | BH6: 8441.49 | BI6: 8584.35 | BJ6: 8312.92 | BK6: 8294.52 | BL6: 8191.97 | BM6: 8109.3 | BN6: 8043.43 | BO6: 8040.38 | BP6: 8002.5 | BQ6: =((AV6/BF6)^(1/(2010-2000)))-1 -> 0.0090674403 | BR6: =((AM6/AV6)^(1/(2019-2010)))-1 -> 0.0060551891
A7: WORLD | B7: World | C7: =VLOOKUP(historical_emissions[[#This Row],[Country]],'Liste-Pays'!A:B,2,0) -> World | D7: Climate Watch | E7: Manufacturing/Construction | F7: CO2 | G7: MtCO₂e | H7: =I7*(1+$BR7) -> 10371.955 | I7: =J7*(1+$BR7) -> 10345.92 | J7: =K7*(1+$BR7) -> 10319.951 | K7: =L7*(1+$BR7) -> 10294.046 | L7: =M7*(1+$BR7) -> 10268.207 | M7: =N7*(1+$BR7) -> 10242.432 | N7: =O7*(1+$BR7) -> 10216.722 | O7: =P7*(1+$BR7) -> 10191.077 | ... Y7: =Z7*(1+$BR7) -> 9938.1368 | Z7: =AA7*(1+$BQ7) -> 9913.1907 | AA7: =AB7*(1+$BQ7) -> 9467.9842 | AB7: =AC7*(1+$BQ7) -> 9042.7722 | AC7: =AD7*(1+$BQ7) -> 8636.6566 | AD7: =AE7*(1+$BQ7) -> 8248.78 | AE7: =AF7*(1+$BQ7) -> 7878.323 | AF7: =AG7*(1+$BQ7) -> 7524.5035 | AG7: =AH7*(1+$BQ7) -> 7186.5742 | ... AI7: =AJ7*(1+$BQ7) -> 6555.5637 | AJ7: 6261.15 | AK7: 6306.66 | AL7: 6160.6 | AM7: 6205.92 | AN7: 6164.75 | AO7: 6037.79 | AP7: 6115.88 | AQ7: 6272.65 | AR7: 6388.96 | AS7: 6320.66 | AT7: 6318.53 | AU7: 6295.4 | AV7: 6067.12 | AW7: 5509.25 | AX7: 5519.5 | AY7: 5412.75 | AZ7: 5133.59 | BA7: 4899.69 | BB7: 4481.47 | BC7: 4056.41 | BD7: 3865.78 | BE7: 3854.14 | BF7: 3831.98 | BG7: 3676.38 | BH7: 3834.39 | BI7: 3836.76 | BJ7: 3812.96 | BK7: 3930.35 | BL7: 3707.52 | BM7: 3694.72 | BN7: 3746.08 | BO7: 3875.35 | BP7: 3953.61 | BQ7: =((AV7/BF7)^(1/(2010-2000)))-1 -> 0.047022308 | BR7: =((AM7/AV7)^(1/(2019-2010)))-1 -> 0.0025164551
A8: USA | B8: United States | C8: =VLOOKUP(historical_emissions[[#This Row],[Country]],'Liste-Pays'!A:B,2,0) -> USA | D8: Climate Watch | E8: Energy | F8: CO2 | G8: MtCO₂e | H8: =I8*(1+$BR8) -> 3430.6731 | I8: =J8*(1+$BR8) -> 3474.9281 | J8: =K8*(1+$BR8) -> 3519.7539 | K8: =L8*(1+$BR8) -> 3565.158 | L8: =M8*(1+$BR8) -> 3611.1478 | M8: =N8*(1+$BR8) -> 3657.7309 | N8: =O8*(1+$BR8) -> 3704.9149 | O8: =P8*(1+$BR8) -> 3752.7075 | ... Y8: =Z8*(1+$BR8) -> 4265.8889 | Z8: =AA8*(1+$BQ8) -> 4320.918 | AA8: =AB8*(1+$BQ8) -> 4350.1416 | AB8: =AC8*(1+$BQ8) -> 4379.5628 | AC8: =AD8*(1+$BQ8) -> 4409.1829 | AD8: =AE8*(1+$BQ8) -> 4439.0035 | AE8: =AF8*(1+$BQ8) -> 4469.0257 | AF8: =AG8*(1+$BQ8) -> 4499.2509 | AG8: =AH8*(1+$BQ8) -> 4529.6806 | ... AI8: =AJ8*(1+$BQ8) -> 4591.1587 | AJ8: 4622.21 | AK8: 4565.34 | AL8: 4279.28 | AM8: 4776.46 | AN8: 4936.26 | AO8: 4778.77 | AP8: 4852.38 | AQ8: 4950.36 | AR8: 5067.36 | AS8: 5055.43 | AT8: 4920.45 | AU8: 5141.12 | AV8: 5360.49 | AW8: 5126.69 | AX8: 5516.87 | AY8: 5690.73 | AZ8: 5606.16 | BA8: 5707.22 | BB8: 5692.32 | BC8: 5615.55 | BD8: 5549.78 | BE8: 5706.56 | BF8: 5734.27 | BG8: 5568.68 | BH8: 5550.97 | BI8: 5504.67 | BJ8: 5236.07 | BK8: 5079.84 | BL8: 5030.37 | BM8: 4960.22 | BN8: 4846.46 | BO8: 4774.58 | BP8: 4810.88 | BQ8: =((AV8/BF8)^(1/(2010-2000)))-1 -> -0.0067178403 | BR8: =((AM8/AV8)^(1/(2019-2010)))-1 -> -0.012735509
A9: USA | B9: United States | C9: =VLOOKUP(historical_emissions[[#This Row],[Country]],'Liste-Pays'!A:B,2,0) -> USA | D9: Climate Watch | E9: Total including LUCF | F9: CO2 | G9: MtCO₂e | H9: =I9*(1+$BR9) -> 3496.7834 | I9: =J9*(1+$BR9) -> 3529.6862 | J9: =K9*(1+$BR9) -> 3562.8987 | K9: =L9*(1+$BR9) -> 3596.4236 | L9: =M9*(1+$BR9) -> 3630.264 | M9: =N9*(1+$BR9) -> 3664.4228 | N9: =O9*(1+$BR9) -> 3698.903 | O9: =P9*(1+$BR9) -> 3733.7076 | ... Y9: =Z9*(1+$BR9) -> 4100.2844 | Z9: =AA9*(1+$BQ9) -> 4138.8658 | AA9: =AB9*(1+$BQ9) -> 4168.2824 | AB9: =AC9*(1+$BQ9) -> 4197.908 | AC9: =AD9*(1+$BQ9) -> 4227.7441 | AD9: =AE9*(1+$BQ9) -> 4257.7923 | AE9: =AF9*(1+$BQ9) -> 4288.0541 | AF9: =AG9*(1+$BQ9) -> 4318.531 | AG9: =AH9*(1+$BQ9) -> 4349.2245 | ... AI9: =AJ9*(1+$BQ9) -> 4411.2674 | AJ9: 4442.62 | AK9: 4385.2 | AL9: 4098.51 | AM9: 4595.91 | AN9: 4753.64 | AO9: 4597.37 | AP9: 4670.14 | AQ9: 4581.1 | AR9: 4697.67 | AS9: 4682.73 | AT9: 4546.76 | AU9: 4764.43 | AV9: 5000.09 | AW9: 4764.45 | AX9: 5166.47 | AY9: 5344.48 | AZ9: 5261.31 | BA9: 5361.77 | BB9: 5346.62 | BC9: 5267.34 | BD9: 5201.38 | BE9: 5356.61 | BF9: 5367.05 | BG9: 5200.16 | BH9: 5181.57 | BI9: 5134.31 | BJ9: 4864.47 | BK9: 4708.07 | BL9: 4657.6 | BM9: 4586.13 | BN9: 4470.67 | BO9: 4398.54 | BP9: 4435.58 | BQ9: =((AV9/BF9)^(1/(2010-2000)))-1 -> -0.0070572297 | BR9: =((AM9/AV9)^(1/(2019-2010)))-1 -> -0.0093217401
A10: WORLD | B10: World | C10: =VLOOKUP(historical_emissions[[#This Row],[Country]],'Liste-Pays'!A:B,2,0) -> World | D10: Climate Watch | E10: Agriculture | F10: CH4 | G10: MtCO₂e | H10: =I10*(1+$BR10) -> 4540.0515 | I10: =J10*(1+$BR10) -> 4523.0232 | J10: =K10*(1+$BR10) -> 4506.0587 | K10: =L10*(1+$BR10) -> 4489.1579 | L10: =M10*(1+$BR10) -> 4472.3204 | M10: =N10*(1+$BR10) -> 4455.5461 | N10: =O10*(1+$BR10) -> 4438.8348 | O10: =P10*(1+$BR10) -> 4422.1861 | ... Y10: =Z10*(1+$BR10) -> 4259.0952 | Z10: =AA10*(1+$BQ10) -> 4243.1206 | AA10: =AB10*(1+$BQ10) -> 4219.3418 | AB10: =AC10*(1+$BQ10) -> 4195.6962 | AC10: =AD10*(1+$BQ10) -> 4172.1831 | AD10: =AE10*(1+$BQ10) -> 4148.8018 | AE10: =AF10*(1+$BQ10) -> 4125.5515 | AF10: =AG10*(1+$BQ10) -> 4102.4315 | AG10: =AH10*(1+$BQ10) -> 4079.4411 | ... AI10: =AJ10*(1+$BQ10) -> 4033.8461 | AJ10: 4011.24 | AK10: 3989.49 | AL10: 3954.26 | AM10: 3899.96 | AN10: 3907.4 | AO10: 3913.32 | AP10: 3876.01 | AQ10: 3849.35 | AR10: 3834.73 | AS10: 3808.94 | AT10: 3846.45 | AU10: 3829.85 | AV10: 3770.27 | AW10: 3748.3 | AX10: 3758.43 | AY10: 3741.54 | AZ10: 3705.88 | BA10: 3673.54 | BB10: 3640.75 | BC10: 3581.07 | BD10: 3582.42 | BE10: 3557.96 | BF10: 3564.23 | BG10: 3559.92 | BH10: 3524.64 | BI10: 3499.64 | BJ10: 3549.31 | BK10: 3551.29 | BL10: 3532.76 | BM10: 3504.67 | BN10: 3522.52 | BO10: 3538.85 | BP10: 3539.61 | BQ10: =((AV10/BF10)^(1/(2010-2000)))-1 -> 0.0056356785 | BR10: =((AM10/AV10)^(1/(2019-2010)))-1 -> 0.0037648114
A11: WORLD | B11: World | C11: =VLOOKUP(historical_emissions[[#This Row],[Country]],'Liste-Pays'!A:B,2,0) -> World | D11: Climate Watch | E11: Energy | F11: CH4 | G11: MtCO₂e | H11: =I11*(1+$BR11) -> 4581.1055 | I11: =J11*(1+$BR11) -> 4570.1348 | J11: =K11*(1+$BR11) -> 4559.1904 | K11: =L11*(1+$BR11) -> 4548.2722 | L11: =M11*(1+$BR11) -> 4537.3801 | M11: =N11*(1+$BR11) -> 4526.5142 | N11: =O11*(1+$BR11) -> 4515.6742 | O11: =P11*(1+$BR11) -> 4504.8602 | ... Y11: =Z11*(1+$BR11) -> 4398.1344 | Z11: =AA11*(1+$BQ11) -> 4387.6018 | AA11: =AB11*(1+$BQ11) -> 4317.7639 | AB11: =AC11*(1+$BQ11) -> 4249.0376 | AC11: =AD11*(1+$BQ11) -> 4181.4052 | AD11: =AE11*(1+$BQ11) -> 4114.8493 | AE11: =AF11*(1+$BQ11) -> 4049.3528 | AF11: =AG11*(1+$BQ11) -> 3984.8988 | AG11: =AH11*(1+$BQ11) -> 3921.4707 | ... AI11: =AJ11*(1+$BQ11) -> 3797.6273 | AJ11: 3737.18 | AK11: 3658.37 | AL11: 3565.64 | AM11: 3837.43 | AN11: 3808.35 | AO11: 3744.09 | AP11: 3721.26 | AQ11: 3785.7 | AR11: 3833.65 | AS11: 3821.81 | AT11: 3822.18 | AU11: 3827.27 | AV11: 3755.51 | AW11: 3630.61 | AX11: 3713.67 | AY11: 3680.16 | AZ11: 3637.8 | BA11: 3588.98 | BB11: 3474.69 | BC11: 3364.9 | BD11: 3226.82 | BE11: 3231.32 | BF11: 3198.79 | BG11: 3105.5 | BH11: 3123.0 | BI11: 3134.54 | BJ11: 3103.87 | BK11: 3058.16 | BL11: 2979.44 | BM11: 2992.46 | BN11: 2974.93 | BO11: 3024.86 | BP11: 3010.77 | BQ11: =((AV11/BF11)^(1/(2010-2000)))-1 -> 0.016174563 | BR11: =((AM11/AV11)^(1/(2019-2010)))-1 -> 0.0024005185
A12: WORLD | B12: World | C12: =VLOOKUP(historical_emissions[[#This Row],[Country]],'Liste-Pays'!A:B,2,0) -> World | D12: Climate Watch | E12: Total including LUCF | F12: N2O | G12: MtCO₂e | H12: =I12*(1+$BR12) -> 3707.6786 | I12: =J12*(1+$BR12) -> 3676.0815 | J12: =K12*(1+$BR12) -> 3644.7536 | K12: =L12*(1+$BR12) -> 3613.6926 | L12: =M12*(1+$BR12) -> 3582.8964 | M12: =N12*(1+$BR12) -> 3552.3626 | N12: =O12*(1+$BR12) -> 3522.0891 | O12: =P12*(1+$BR12) -> 3492.0735 | ... Y12: =Z12*(1+$BR12) -> 3205.6329 | Z12: =AA12*(1+$BQ12) -> 3178.3142 | AA12: =AB12*(1+$BQ12) -> 3131.8149 | AB12: =AC12*(1+$BQ12) -> 3085.9959 | AC12: =AD12*(1+$BQ12) -> 3040.8472 | AD12: =AE12*(1+$BQ12) -> 2996.3591 | AE12: =AF12*(1+$BQ12) -> 2952.5218 | AF12: =AG12*(1+$BQ12) -> 2909.3259 | AG12: =AH12*(1+$BQ12) -> 2866.7619 | ... AI12: =AJ12*(1+$BQ12) -> 2783.493 | AJ12: 2742.77 | AK12: 2768.58 | AL12: 2751.11 | AM12: 2713.81 | AN12: 2690.9 | AO12: 2704.83 | AP12: 2648.83 | AQ12: 2628.24 | AR12: 2608.59 | AS12: 2570.39 | AT12: 2581.32 | AU12: 2565.36 | AV12: 2512.62 | AW12: 2430.64 | AX12: 2429.76 | AY12: 2462.67 | AZ12: 2399.34 | BA12: 2376.5 | BB12: 2362.44 | BC12: 2288.2 | BD12: 2252.06 | BE12: 2200.72 | BF12: 2168.3 | BG12: 2178.87 | BH12: 2190.7 | BI12: 2164.4 | BJ12: 2178.4 | BK12: 2176.06 | BL12: 2129.65 | BM12: 2105.36 | BN12: 2120.64 | BO12: 2124.43 | BP12: 2141.01 | BQ12: =((AV12/BF12)^(1/(2010-2000)))-1 -> 0.014847402 | BR12: =((AM12/AV12)^(1/(2019-2010)))-1 -> 0.0085953428
A13: WORLD | B13: World | C13: =VLOOKUP(historical_emissions[[#This Row],[Country]],'Liste-Pays'!A:B,2,0) -> World | D13: Climate Watch | E13: Building | F13: CO2 | G13: MtCO₂e | H13: =I13*(1+$BR13) -> 3072.2848 | I13: =J13*(1+$BR13) -> 3063.4517 | J13: =K13*(1+$BR13) -> 3054.644 | K13: =L13*(1+$BR13) -> 3045.8616 | L13: =M13*(1+$BR13) -> 3037.1044 | M13: =N13*(1+$BR13) -> 3028.3725 | N13: =O13*(1+$BR13) -> 3019.6656 | O13: =P13*(1+$BR13) -> 3010.9838 | ... Y13: =Z13*(1+$BR13) -> 2925.5266 | Z13: =AA13*(1+$BQ13) -> 2917.1154 | AA13: =AB13*(1+$BQ13) -> 2896.5463 | AB13: =AC13*(1+$BQ13) -> 2876.1223 | AC13: =AD13*(1+$BQ13) -> 2855.8423 | AD13: =AE13*(1+$BQ13) -> 2835.7052 | AE13: =AF13*(1+$BQ13) -> 2815.7102 | AF13: =AG13*(1+$BQ13) -> 2795.8561 | AG13: =AH13*(1+$BQ13) -> 2776.1421 | ... AI13: =AJ13*(1+$BQ13) -> 2737.13 | AJ13: 2717.83 | AK13: 2775.56 | AL13: 2734.12 | AM13: 2781.05 | AN13: 2818.88 | AO13: 2786.35 | AP13: 2720.33 | AQ13: 2688.7 | AR13: 2656.94 | AS13: 2710.26 | AT13: 2600.06 | AU13: 2656.69 | AV13: 2709.91 | AW13: 2654.73 | AX13: 2705.77 | AY13: 2640.0 | AZ13: 2641.28 | BA13: 2672.43 | BB13: 2672.75 | BC13: 2631.27 | BD13: 2547.09 | BE13: 2548.51 | BF13: 2524.78 | BG13: 2531.69 | BH13: 2461.89 | BI13: 2611.63 | BJ13: 2635.45 | BK13: 2567.4 | BL13: 2492.5 | BM13: 2572.89 | BN13: 2513.78 | BO13: 2620.9 | BP13: 2594.24 | BQ13: =((AV13/BF13)^(1/(2010-2000)))-1 -> 0.0071012445 | BR13: =((AM13/AV13)^(1/(2019-2010)))-1 -> 0.0028833857
... A473: IND | B473: India | C473: =VLOOKUP(historical_emissions[[#This Row],[Country]],'Liste-Pays'!A:B,2,0) -> IND | D473: Climate Watch | E473: Energy | F473: N2O | G473: MtCO₂e | H473: =I473*(1+$BR473) -> 66.877307 | I473: =J473*(1+$BR473) -> 64.420391 | J473: =K473*(1+$BR473) -> 62.053736 | K473: =L473*(1+$BR473) -> 59.774027 | L473: =M473*(1+$BR473) -> 57.578068 | M473: =N473*(1+$BR473) -> 55.462784 | N473: =O473*(1+$BR473) -> 53.425211 | O473: =P473*(1+$BR473) -> 51.462493 | ... Y473: =Z473*(1+$BR473) -> 35.394567 | Z473: =AA473*(1+$BQ473) -> 34.094253 | AA473: =AB473*(1+$BQ473) -> 32.723694 | AB473: =AC473*(1+$BQ473) -> 31.40823 | AC473: =AD473*(1+$BQ473) -> 30.145647 | AD473: =AE473*(1+$BQ473) -> 28.933818 | AE473: =AF473*(1+$BQ473) -> 27.770704 | AF473: =AG473*(1+$BQ473) -> 26.654346 | AG473: =AH473*(1+$BQ473) -> 25.582865 | ... AI473: =AJ473*(1+$BQ473) -> 23.567388 | AJ473: 22.62 | AK473: 21.03 | AL473: 19.39 | AM473: 20.35 | AN473: 20.39 | AO473: 19.56 | AP473: 18.46 | AQ473: 18.09 | AR473: 17.57 | AS473: 16.55 | AT473: 16.04 | AU473: 15.17 | AV473: 14.53 | AW473: 13.72 | AX473: 13.06 | AY473: 12.36 | AZ473: 11.53 | BA473: 11.07 | BB473: 10.65 | BC473: 10.16 | BD473: 10.01 | BE473: 9.83 | BF473: 9.64 | BG473: 9.4 | BH473: 9.14 | BI473: 9.02 | BJ473: 8.83 | BK473: 8.5 | BL473: 8.19 | BM473: 7.95 | BN473: 7.72 | BO473: 7.58 | BP473: 7.32 | BQ473: =((AV473/BF473)^(1/(2010-2000)))-1 -> 0.041882775 | BR473: =((AM473/AV473)^(1/(2019-2010)))-1 -> 0.038138798
A474: RUS | B474: Russia | C474: =VLOOKUP(historical_emissions[[#This Row],[Country]],'Liste-Pays'!A:B,2,0) -> FSU | D474: Climate Watch | E474: Industrial Processes | F474: CO2 | G474: MtCO₂e | H474: =I474*(1+$BR474) -> 27.155356 | I474: =J474*(1+$BR474) -> 27.495804 | J474: =K474*(1+$BR474) -> 27.840521 | K474: =L474*(1+$BR474) -> 28.18956 | L474: =M474*(1+$BR474) -> 28.542975 | M474: =N474*(1+$BR474) -> 28.90082 | N474: =O474*(1+$BR474) -> 29.263152 | O474: =P474*(1+$BR474) -> 29.630026 | ... Y474: =Z474*(1+$BR474) -> 33.5615 | Z474: =AA474*(1+$BQ474) -> 33.982263 | AA474: =AB474*(1+$BQ474) -> 32.624053 | AB474: =AC474*(1+$BQ474) -> 31.320128 | AC474: =AD474*(1+$BQ474) -> 30.068319 | AD474: =AE474*(1+$BQ474) -> 28.866542 | AE474: =AF474*(1+$BQ474) -> 27.712798 | AF474: =AG474*(1+$BQ474) -> 26.605167 | AG474: =AH474*(1+$BQ474) -> 25.541806 | ... AI474: =AJ474*(1+$BQ474) -> 23.540887 | AJ474: 22.6 | AK474: 22.16 | AL474: 20.58 | AM474: 20.31 | AN474: 20.09 | AO474: 20.51 | AP474: 20.43 | AQ474: 23.17 | AR474: 26.45 | AS474: 27.28 | AT474: 26.33 | AU474: 25.13 | AV474: 22.72 | AW474: 19.75 | AX474: 23.63 | AY474: 27.64 | AZ474: 24.54 | BA474: 22.26 | BB474: 20.92 | BC474: 18.67 | BD474: 17.12 | BE474: 15.86 | BF474: 15.11 | BG474: 13.17 | BH474: 11.92 | BI474: 12.27 | BJ474: 12.72 | BK474: 16.65 | BL474: 16.48 | BM474: 21.99 | BN474: 26.72 | BO474: N/A | BQ474: =((AV474/BF474)^(1/(2010-2000)))-1 -> 0.041632175 | BR474: =((AM474/AV474)^(1/(2019-2010)))-1 -> -0.012381842
A475: ESP | B475: Spain | C475: =VLOOKUP(historical_emissions[[#This Row],[Country]],'Liste-Pays'!A:B,2,0) -> WEU | D475: Climate Watch | E475: Building | F475: CO2 | G475: MtCO₂e | H475: =I475*(1+$BR475) -> 19.718077 | I475: =J475*(1+$BR475) -> 20.022752 | J475: =K475*(1+$BR475) -> 20.332135 | K475: =L475*(1+$BR475) -> 20.646299 | L475: =M475*(1+$BR475) -> 20.965316 | M475: =N475*(1+$BR475) -> 21.289264 | N475: =O475*(1+$BR475) -> 21.618216 | O475: =P475*(1+$BR475) -> 21.952252 | ... Y475: =Z475*(1+$BR475) -> 25.590057 | Z475: =AA475*(1+$BQ475) -> 25.985463 | AA475: =AB475*(1+$BQ475) -> 25.619584 | AB475: =AC475*(1+$BQ475) -> 25.258856 | AC475: =AD475*(1+$BQ475) -> 24.903208 | AD475: =AE475*(1+$BQ475) -> 24.552567 | AE475: =AF475*(1+$BQ475) -> 24.206863 | AF475: =AG475*(1+$BQ475) -> 23.866026 | AG475: =AH475*(1+$BQ475) -> 23.529989 | ... AI475: =AJ475*(1+$BQ475) -> 22.872042 | AJ475: 22.55 | AK475: 24.35 | AL475: 23.28 | AM475: 23.72 | AN475: 25.46 | AO475: 24.02 | AP475: 24.2 | AQ475: 24.23 | AR475: 22.42 | AS475: 23.91 | AT475: 24.73 | AU475: 25.07 | AV475: 27.23 | AW475: 25.58 | AX475: 25.98 | AY475: 26.79 | AZ475: 27.43 | BA475: 28.71 | BB475: 27.71 | BC475: 25.6 | BD475: 24.94 | BE475: 24.41 | BF475: 23.63 | BG475: 21.84 | BH475: 20.55 | BI475: 20.0 | BJ475: 19.93 | BK475: 18.9 | BL475: 19.02 | BM475: 18.0 | BN475: 18.81 | BO475: 18.21 | BP475: 16.19 | BQ475: =((AV475/BF475)^(1/(2010-2000)))-1 -> 0.014281238 | BR475: =((AM475/AV475)^(1/(2019-2010)))-1 -> -0.015216456
A476: JPN | B476: Japan | C476: =VLOOKUP(historical_emissions[[#This Row],[Country]],'Liste-Pays'!A:B,2,0) -> JPN | D476: Climate Watch | E476: Industrial Processes | F476: CO2 | G476: MtCO₂e | H476: =I476*(1+$BR476) -> 16.901286 | I476: =J476*(1+$BR476) -> 16.825045 | J476: =K476*(1+$BR476) -> 16.749148 | K476: =L476*(1+$BR476) -> 16.673593 | L476: =M476*(1+$BR476) -> 16.59838 | M476: =N476*(1+$BR476) -> 16.523505 | N476: =O476*(1+$BR476) -> 16.448968 | O476: =P476*(1+$BR476) -> 16.374768 | ... Y476: =Z476*(1+$BR476) -> 15.650925 | Z476: =AA476*(1+$BQ476) -> 15.580325 | AA476: =AB476*(1+$BQ476) -> 16.162126 | AB476: =AC476*(1+$BQ476) -> 16.765653 | AC476: =AD476*(1+$BQ476) -> 17.391717 | AD476: =AE476*(1+$BQ476) -> 18.041159 | AE476: =AF476*(1+$BQ476) -> 18.714852 | AF476: =AG476*(1+$BQ476) -> 19.413703 | AG476: =AH476*(1+$BQ476) -> 20.138651 | ... AI476: =AJ476*(1+$BQ476) -> 21.670769 | AJ476: 22.48 | AK476: 24.4 | AL476: 24.49 | AM476: 25.33 | AN476: 26.18 | AO476: 26.43 | AP476: 25.97 | AQ476: 25.94 | AR476: 26.56 | AS476: 26.81 | AT476: 25.62 | AU476: 24.98 | AV476: 24.32 | AW476: 25.31 | AX476: 28.55 | AY476: 30.66 | AZ476: 31.99 | BA476: 32.28 | BB476: 31.28 | BC476: 31.94 | BD476: 32.42 | BE476: 34.37 | BF476: 35.09 | BG476: 35.01 | BH476: 35.36 | BI476: 39.93 | BJ476: 42.56 | BK476: 42.14 | BL476: 42.3 | BM476: 41.22 | BN476: 41.67 | BO476: 40.35 | BP476: 38.7 | BQ476: =((AV476/BF476)^(1/(2010-2000)))-1 -> -0.035997811 | BR476: =((AM476/AV476)^(1/(2019-2010)))-1 -> 0.0045313922
A477: SWE | B477: Sweden | C477: =VLOOKUP(historical_emissions[[#This Row],[Country]],'Liste-Pays'!A:B,2,0) -> WEU | D477: Climate Watch | E477: Total including LUCF | F477: CO2 | G477: MtCO₂e | H477: =I477*(1+$BR477) -> 5.3096154 | I477: =J477*(1+$BR477) -> 5.6391014 | J477: =K477*(1+$BR477) -> 5.9890336 | K477: =L477*(1+$BR477) -> 6.3606806 | L477: =M477*(1+$BR477) -> 6.7553901 | M477: =N477*(1+$BR477) -> 7.1745931 | N477: =O477*(1+$BR477) -> 7.6198096 | O477: =P477*(1+$BR477) -> 8.0926538 | ... Y477: =Z477*(1+$BR477) -> 14.776085 | Z477: =AA477*(1+$BQ477) -> 15.69301 | AA477: =AB477*(1+$BQ477) -> 16.265843 | AB477: =AC477*(1+$BQ477) -> 16.859587 | AC477: =AD477*(1+$BQ477) -> 17.475004 | AD477: =AE477*(1+$BQ477) -> 18.112886 | AE477: =AF477*(1+$BQ477) -> 18.774051 | AF477: =AG477*(1+$BQ477) -> 19.459351 | AG477: =AH477*(1+$BQ477) -> 20.169666 | ... AI477: =AJ477*(1+$BQ477) -> 21.669026 | AJ477: 22.46 | AK477: 25.1 | AL477: 22.63 | AM477: 23.93 | AN477: 24.36 | AO477: 25.99 | AP477: 26.28 | AQ477: 21.26 | AR477: 21.12 | AS477: 22.42 | AT477: 24.02 | AU477: 26.42 | AV477: 41.14 | AW477: 35.66 | AX477: 38.75 | AY477: 39.68 | AZ477: 41.29 | BA477: 42.57 | BB477: 45.88 | BC477: 47.33 | BD477: 46.08 | BE477: 44.53 | BF477: 58.88 | BG477: 62.69 | BH477: 63.69 | BI477: 62.67 | BJ477: 68.93 | BK477: 63.5 | BL477: 63.74 | BM477: 61.75 | BN477: 62.0 | BO477: 59.49 | BP477: 58.6 | BQ477: =((AV477/BF477)^(1/(2010-2000)))-1 -> -0.035216986 | BR477: =((AM477/AV477)^(1/(2019-2010)))-1 -> -0.05842882
A478: MDG | B478: Madagascar | C478: =VLOOKUP(historical_emissions[[#This Row],[Country]],'Liste-Pays'!A:B,2,0) -> AFR | D478: Climate Watch | E478: Total including LUCF | F478: CH4 | G478: MtCO₂e | H478: =I478*(1+$BR478) -> 25.979717 | I478: =J478*(1+$BR478) -> 25.839583 | J478: =K478*(1+$BR478) -> 25.700206 | K478: =L478*(1+$BR478) -> 25.56158 | L478: =M478*(1+$BR478) -> 25.423702 | M478: =N478*(1+$BR478) -> 25.286567 | N478: =O478*(1+$BR478) -> 25.150172 | O478: =P478*(1+$BR478) -> 25.014513 | ... Y478: =Z478*(1+$BR478) -> 23.697524 | Z478: =AA478*(1+$BQ478) -> 23.569701 | AA478: =AB478*(1+$BQ478) -> 23.455262 | AB478: =AC478*(1+$BQ478) -> 23.34138 | AC478: =AD478*(1+$BQ478) -> 23.22805 | AD478: =AE478*(1+$BQ478) -> 23.11527 | AE478: =AF478*(1+$BQ478) -> 23.003039 | AF478: =AG478*(1+$BQ478) -> 22.891352 | AG478: =AH478*(1+$BQ478) -> 22.780207 | ... AI478: =AJ478*(1+$BQ478) -> 22.559534 | AJ478: 22.45 | AK478: 22.21 | AL478: 22.49 | AM478: 22.1 | AN478: 21.35 | AO478: 21.91 | AP478: 22.41 | AQ478: 20.48 | AR478: 20.38 | AS478: 19.66 | AT478: 20.68 | AU478: 20.56 | AV478: 21.05 | AW478: 20.75 | AX478: 20.07 | AY478: 20.78 | AZ478: 20.01 | BA478: 21.14 | BB478: 18.54 | BC478: 19.14 | BD478: 17.9 | BE478: 19.24 | BF478: 20.05 | BG478: 20.88 | BH478: 21.07 | BI478: 20.34 | BJ478: 20.76 | BK478: 20.11 | BL478: 19.7 | BM478: 20.08 | BN478: 19.74 | BO478: 19.5 | BP478: 19.55 | BQ478: =((AV478/BF478)^(1/(2010-2000)))-1 -> 0.0048790044 | BR478: =((AM478/AV478)^(1/(2019-2010)))-1 -> 0.0054232136
A479: OMN | B479: Oman | C479: =VLOOKUP(historical_emissions[[#This Row],[Country]],'Liste-Pays'!A:B,2,0) -> MEA | D479: Climate Watch | E479: Total including LUCF | F479: CH4 | G479: MtCO₂e | H479: =I479*(1+$BR479) -> 39.840488 | I479: =J479*(1+$BR479) -> 38.664042 | J479: =K479*(1+$BR479) -> 37.522336 | K479: =L479*(1+$BR479) -> 36.414342 | L479: =M479*(1+$BR479) -> 35.339067 | M479: =N479*(1+$BR479) -> 34.295543 | N479: =O479*(1+$BR479) -> 33.282833 | O479: =P479*(1+$BR479) -> 32.300028 | ... Y479: =Z479*(1+$BR479) -> 23.934753 | Z479: =AA479*(1+$BQ479) -> 23.227986 | AA479: =AB479*(1+$BQ479) -> 23.144862 | AB479: =AC479*(1+$BQ479) -> 23.062035 | AC479: =AD479*(1+$BQ479) -> 22.979504 | AD479: =AE479*(1+$BQ479) -> 22.897269 | AE479: =AF479*(1+$BQ479) -> 22.815328 | AF479: =AG479*(1+$BQ479) -> 22.73368 | AG479: =AH479*(1+$BQ479) -> 22.652324 | ... AI479: =AJ479*(1+$BQ479) -> 22.490485 | AJ479: 22.41 | AK479: 21.77 | AL479: 21.19 | AM479: 21.57 | AN479: 21.34 | AO479: 20.9 | AP479: 20.93 | AQ479: 20.21 | AR479: 19.87 | AS479: 19.65 | AT479: 18.35 | AU479: 17.07 | AV479: 16.47 | AW479: 15.91 | AX479: 15.36 | AY479: 14.9 | AZ479: 15.45 | BA479: 15.89 | BB479: 15.85 | BC479: 16.31 | BD479: 16.18 | BE479: 16.57 | BF479: 15.89 | BG479: 14.78 | BH479: 14.3 | BI479: 14.89 | BJ479: 14.14 | BK479: 13.66 | BL479: 12.73 | BM479: 11.56 | BN479: 10.11 | BO479: 9.43 | BP479: 9.1 | BQ479: =((AV479/BF479)^(1/(2010-2000)))-1 -> 0.0035914904 | BR479: =((AM479/AV479)^(1/(2019-2010)))-1 -> 0.030427389
A480: LKA | B480: Sri Lanka | C480: =VLOOKUP(historical_emissions[[#This Row],[Country]],'Liste-Pays'!A:B,2,0) -> ODA | D480: Climate Watch | E480: Total including LUCF | F480: CO2 | G480: MtCO₂e | H480: =I480*(1+$BR480) -> 61.69499 | I480: =J480*(1+$BR480) -> 58.316919 | J480: =K480*(1+$BR480) -> 55.123813 | K480: =L480*(1+$BR480) -> 52.105543 | L480: =M480*(1+$BR480) -> 49.252537 | M480: =N480*(1+$BR480) -> 46.555745 | N480: =O480*(1+$BR480) -> 44.006615 | O480: =P480*(1+$BR480) -> 41.59706 | ... Y480: =Z480*(1+$BR480) -> 23.686965 | Z480: =AA480*(1+$BQ480) -> 22.39 | AA480: =AB480*(1+$BQ480) -> 22.39 | AB480: =AC480*(1+$BQ480) -> 22.39 | AC480: =AD480*(1+$BQ480) -> 22.39 | AD480: =AE480*(1+$BQ480) -> 22.39 | AE480: =AF480*(1+$BQ480) -> 22.39 | AF480: =AG480*(1+$BQ480) -> 22.39 | AG480: =AH480*(1+$BQ480) -> 22.39 | ... AI480: =AJ480*(1+$BQ480) -> 22.39 | AJ480: 22.39 | AK480: 24.5 | AL480: 24.11 | AM480: 25.58 | AN480: 23.5 | AO480: 24.95 | AP480: 24.97 | AQ480: 19.74 | AR480: 17.96 | AS480: 14.96 | AT480: 17.96 | AU480: 15.94 | AV480: 15.41 | AW480: 14.63 | AX480: 15.15 | AY480: 15.94 | AZ480: 14.77 | BA480: 16.35 | BB480: 15.24 | BC480: 14.78 | BD480: 13.75 | BE480: 13.21 | BF480: 15.41 | BG480: 13.98 | BH480: 13.09 | BI480: 12.82 | BJ480: 12.84 | BK480: 10.3 | BL480: 10.25 | BM480: 9.57 | BN480: 9.73 | BO480: 8.47 | BP480: 8.32 | BQ480: =((AV480/BF480)^(1/(2010-2000)))-1 -> 0 | BR480: =((AM480/AV480)^(1/(2019-2010)))-1 -> 0.057926077
A481: NPL | B481: Nepal | C481: =VLOOKUP(historical_emissions[[#This Row],[Country]],'Liste-Pays'!A:B,2,0) -> ODA | D481: Climate Watch | E481: Agriculture | F481: CH4 | G481: MtCO₂e | H481: =I481*(1+$BR481) -> 29.639399 | I481: =J481*(1+$BR481) -> 29.411067 | J481: =K481*(1+$BR481) -> 29.184495 | K481: =L481*(1+$BR481) -> 28.959667 | L481: =M481*(1+$BR481) -> 28.736572 | M481: =N481*(1+$BR481) -> 28.515195 | N481: =O481*(1+$BR481) -> 28.295524 | O481: =P481*(1+$BR481) -> 28.077545 | ... Y481: =Z481*(1+$BR481) -> 25.98801 | Z481: =AA481*(1+$BQ481) -> 25.787807 | AA481: =AB481*(1+$BQ481) -> 25.424884 | AB481: =AC481*(1+$BQ481) -> 25.067069 | AC481: =AD481*(1+$BQ481) -> 24.714289 | AD481: =AE481*(1+$BQ481) -> 24.366474 | AE481: =AF481*(1+$BQ481) -> 24.023554 | AF481: =AG481*(1+$BQ481) -> 23.68546 | AG481: =AH481*(1+$BQ481) -> 23.352124 | ... AI481: =AJ481*(1+$BQ481) -> 22.699459 | AJ481: 22.38 | AK481: 22.51 | AL481: 22.48 | AM481: 22.31 | AN481: 22.21 | AO481: 21.85 | AP481: 22.06 | AQ481: 21.27 | AR481: 21.48 | AS481: 21.73 | AT481: 21.26 | AU481: 21.26 | AV481: 20.81 | AW481: 20.41 | AX481: 20.19 | AY481: 19.86 | AZ481: 19.16 | BA481: 19.24 | BB481: 18.95 | BC481: 18.76 | BD481: 18.45 | BE481: 18.31 | BF481: 18.06 | BG481: 18.07 | BH481: 17.94 | BI481: 17.68 | BJ481: 17.49 | BK481: 17.3 | BL481: 16.8 | BM481: 15.95 | BN481: 16.17 | BO481: 15.58 | BP481: 16.11 | BQ481: =((AV481/BF481)^(1/(2010-2000)))-1 -> 0.014274328 | BR481: =((AM481/AV481)^(1/(2019-2010)))-1 -> 0.007763466
A482: SOM | B482: Somalia | C482: =VLOOKUP(historical_emissions[[#This Row],[Country]],'Liste-Pays'!A:B,2,0) -> AFR | D482: Climate Watch | E482: Total including LUCF | F482: CH4 | G482: MtCO₂e | H482: =I482*(1+$BR482) -> 26.370084 | I482: =J482*(1+$BR482) -> 26.16251 | J482: =K482*(1+$BR482) -> 25.95657 | K482: =L482*(1+$BR482) -> 25.752251 | L482: =M482*(1+$BR482) -> 25.549541 | M482: =N482*(1+$BR482) -> 25.348426 | N482: =O482*(1+$BR482) -> 25.148894 | O482: =P482*(1+$BR482) -> 24.950932 | ... Y482: =Z482*(1+$BR482) -> 23.055031 | Z482: =AA482*(1+$BQ482) -> 22.873552 | AA482: =AB482*(1+$BQ482) -> 22.818607 | AB482: =AC482*(1+$BQ482) -> 22.763793 | AC482: =AD482*(1+$BQ482) -> 22.709112 | AD482: =AE482*(1+$BQ482) -> 22.654561 | AE482: =AF482*(1+$BQ482) -> 22.600142 | AF482: =AG482*(1+$BQ482) -> 22.545853 | AG482: =AH482*(1+$BQ482) -> 22.491695 | ... AI482: =AJ482*(1+$BQ482) -> 22.383769 | AJ482: 22.33 | AK482: 22.33 | AL482: 22.37 | AM482: 22.14 | AN482: 21.99 | AO482: 21.77 | AP482: 21.72 | AQ482: 21.6 | AR482: 21.45 | AS482: 21.24 | AT482: 21.11 | AU482: 20.81 | AV482: 20.62 | AW482: 20.43 | AX482: 20.35 | AY482: 20.27 | AZ482: 20.98 | BA482: 21.85 | BB482: 21.46 | BC482: 21.17 | BD482: 20.94 | BE482: 20.6 | BF482: 20.13 | BG482: 19.85 | BH482: 19.55 | BI482: 19.4 | BJ482: 18.95 | BK482: 18.45 | BL482: 17.87 | BM482: 16.42 | BN482: 14.92 | BO482: 16.3 | BP482: 18.47 | BQ482: =((AV482/BF482)^(1/(2010-2000)))-1 -> 0.0024079183 | BR482: =((AM482/AV482)^(1/(2019-2010)))-1 -> 0.0079340254
A483: UKR | B483: Ukraine | C483: =VLOOKUP(historical_emissions[[#This Row],[Country]],'Liste-Pays'!A:B,2,0) -> FSU | D483: Climate Watch | E483: Other Fuel Combustion | F483: CO2 | G483: MtCO₂e | H483: =I483*(1+$BR483) -> 22.722959 | I483: =J483*(1+$BR483) -> 22.831438 | J483: =K483*(1+$BR483) -> 22.940435 | K483: =L483*(1+$BR483) -> 23.049953 | L483: =M483*(1+$BR483) -> 23.159993 | M483: =N483*(1+$BR483) -> 23.270559 | N483: =O483*(1+$BR483) -> 23.381652 | O483: =P483*(1+$BR483) -> 23.493276 | ... Y483: =Z483*(1+$BR483) -> 24.639247 | Z483: =AA483*(1+$BQ483) -> 24.756875 | AA483: =AB483*(1+$BQ483) -> 24.484048 | AB483: =AC483*(1+$BQ483) -> 24.214227 | AC483: =AD483*(1+$BQ483) -> 23.94738 | AD483: =AE483*(1+$BQ483) -> 23.683473 | AE483: =AF483*(1+$BQ483) -> 23.422475 | AF483: =AG483*(1+$BQ483) -> 23.164353 | AG483: =AH483*(1+$BQ483) -> 22.909076 | ... AI483: =AJ483*(1+$BQ483) -> 22.40693 | AJ483: 22.16 | AK483: 3.65 | AL483: 3.42 | AM483: 4.11 | AN483: 3.91 | AO483: 3.87 | AP483: 4.83 | AQ483: 4.33 | AR483: 4.39 | AS483: 4.84 | AT483: 4.62 | AU483: 4.79 | AV483: 4.29 | AW483: 4.12 | AX483: 4.4 | AY483: 4.17 | AZ483: 4.62 | BA483: 7.99 | BB483: 5.07 | BC483: 4.16 | BD483: 3.99 | BE483: 3.72 | BF483: 3.84 | BG483: 3.77 | BH483: 4.59 | BI483: 5.2 | BJ483: 4.92 | BK483: 6.57 | BL483: 7.86 | BM483: 9.62 | BN483: 12.1 | BO483: 23.89 | BP483: 26.58 | BQ483: =((AV483/BF483)^(1/(2010-2000)))-1 -> 0.011143063 | BR483: =((AM483/AV483)^(1/(2019-2010)))-1 -> -0.0047513105
A484: COD | B484: Democratic Republic of the Congo | C484: =VLOOKUP(historical_emissions[[#This Row],[Country]],'Liste-Pays'!A:B,2,0) -> AFR | D484: Climate Watch | E484: Energy | F484: CH4 | G484: MtCO₂e | H484: =I484*(1+$BR484) -> 33.75542 | I484: =J484*(1+$BR484) -> 33.46165 | J484: =K484*(1+$BR484) -> 33.170437 | K484: =L484*(1+$BR484) -> 32.881757 | L484: =M484*(1+$BR484) -> 32.59559 | M484: =N484*(1+$BR484) -> 32.311914 | N484: =O484*(1+$BR484) -> 32.030706 | O484: =P484*(1+$BR484) -> 31.751946 | ... Y484: =Z484*(1+$BR484) -> 29.094351 | Z484: =AA484*(1+$BQ484) -> 28.841146 | AA484: =AB484*(1+$BQ484) -> 28.089799 | AB484: =AC484*(1+$BQ484) -> 27.358026 | AC484: =AD484*(1+$BQ484) -> 26.645316 | AD484: =AE484*(1+$BQ484) -> 25.951173 | AE484: =AF484*(1+$BQ484) -> 25.275114 | AF484: =AG484*(1+$BQ484) -> 24.616667 | AG484: =AH484*(1+$BQ484) -> 23.975373 | ... AI484: =AJ484*(1+$BQ484) -> 22.742469 | AJ484: 22.15 | AK484: 21.95 | AL484: 20.11 | AM484: 17.58 | AN484: 17.25 | AO484: 20.16 | AP484: 17.25 | AQ484: 16.77 | AR484: 16.27 | AS484: 14.02 | AT484: 12.24 | AU484: 16.87 | AV484: 16.25 | AW484: 16.2 | AX484: 15.92 | AY484: 15.55 | AZ484: 14.94 | BA484: 14.57 | BB484: 14.28 | BC484: 14.07 | BD484: 13.34 | BE484: 13.02 | BF484: 12.48 | BG484: 12.46 | BH484: 12.43 | BI484: 12.35 | BJ484: 12.02 | BK484: 11.42 | BL484: 11.16 | BM484: 10.09 | BN484: 9.1 | BO484: 8.91 | BP484: 8.73 | BQ484: =((AV484/BF484)^(1/(2010-2000)))-1 -> 0.026748029 | BR484: =((AM484/AV484)^(1/(2019-2010)))-1 -> 0.0087793122
A485: MNG | B485: Mongolia | C485: =VLOOKUP(historical_emissions[[#This Row],[Country]],'Liste-Pays'!A:B,2,0) -> ODA-EXCLUDED | D485: Climate Watch | E485: Total including LUCF | F485: CH4 | G485: MtCO₂e | H485: =I485*(1+$BR485) -> 79.22709 | I485: =J485*(1+$BR485) -> 72.771594 | J485: =K485*(1+$BR485) -> 66.842098 | K485: =L485*(1+$BR485) -> 61.395743 | L485: =M485*(1+$BR485) -> 56.393162 | M485: =N485*(1+$BR485) -> 51.798196 | N485: =O485*(1+$BR485) -> 47.577631 | O485: =P485*(1+$BR485) -> 43.700962 | ... Y485: =Z485*(1+$BR485) -> 18.679827 | Z485: =AA485*(1+$BQ485) -> 17.157778 | AA485: =AB485*(1+$BQ485) -> 17.594442 | AB485: =AC485*(1+$BQ485) -> 18.042218 | AC485: =AD485*(1+$BQ485) -> 18.501391 | AD485: =AE485*(1+$BQ485) -> 18.972249 | AE485: =AF485*(1+$BQ485) -> 19.455091 | AF485: =AG485*(1+$BQ485) -> 19.950221 | AG485: =AH485*(1+$BQ485) -> 20.457953 | ... AI485: =AJ485*(1+$BQ485) -> 21.512509 | AJ485: 22.06 | AK485: 20.58 | AL485: 20.45 | AM485: 21.51 | AN485: 20.06 | AO485: 20.0 | AP485: 18.59 | AQ485: 17.04 | AR485: 15.57 | AS485: 13.73 | AT485: 12.78 | AU485: 11.6 | AV485: 10.01 | AW485: 12.22 | AX485: 11.76 | AY485: 11.64 | AZ485: 10.21 | BA485: 9.21 | BB485: 8.3 | BC485: 8.69 | BD485: 8.67 | BE485: 10.63 | BF485: 12.87 | BG485: 12.39 | BH485: 12.29 | BI485: 12.49 | BJ485: 10.98 | BK485: 10.26 | BL485: 9.52 | BM485: 9.7 | BN485: 9.84 | BO485: 10.14 | BP485: 9.83 | BQ485: =((AV485/BF485)^(1/(2010-2000)))-1 -> -0.024818277 | BR485: =((AM485/AV485)^(1/(2019-2010)))-1 -> 0.088709004
A486: DEU | B486: Germany | C486: =VLOOKUP(historical_emissions[[#This Row],[Country]],'Liste-Pays'!A:B,2,0) -> WEU | D486: Climate Watch | E486: Agriculture | F486: N2O | G486: MtCO₂e | H486: =I486*(1+$BR486) -> 16.875409 | I486: =J486*(1+$BR486) -> 17.077273 | J486: =K486*(1+$BR486) -> 17.281551 | K486: =L486*(1+$BR486) -> 17.488272 | L486: =M486*(1+$BR486) -> 17.697467 | M486: =N486*(1+$BR486) -> 17.909164 | N486: =O486*(1+$BR486) -> 18.123393 | O486: =P486*(1+$BR486) -> 18.340185 | ... Y486: =Z486*(1+$BR486) -> 20.655974 | Z486: =AA486*(1+$BQ486) -> 20.903061 | AA486: =AB486*(1+$BQ486) -> 21.006424 | AB486: =AC486*(1+$BQ486) -> 21.110299 | AC486: =AD486*(1+$BQ486) -> 21.214687 | AD486: =AE486*(1+$BQ486) -> 21.319591 | AE486: =AF486*(1+$BQ486) -> 21.425014 | AF486: =AG486*(1+$BQ486) -> 21.530958 | AG486: =AH486*(1+$BQ486) -> 21.637426 | ... AI486: =AJ486*(1+$BQ486) -> 21.851945 | AJ486: 21.96 | AK486: 22.56 | AL486: 23.85 | AM486: 24.7 | AN486: 24.39 | AO486: 25.89 | AP486: 26.84 | AQ486: 27.4 | AR486: 28.19 | AS486: 27.22 | AT486: 26.74 | AU486: 26.52 | AV486: 27.49 | AW486: 26.73 | AX486: 26.67 | AY486: 27.44 | AZ486: 26.4 | BA486: 27.74 | BB486: 27.97 | BC486: 27.95 | BD486: 28.19 | BE486: 28.7 | BF486: 28.88 | BG486: 29.99 | BH486: 29.48 | BI486: 29.18 | BJ486: 28.9 | BK486: 28.97 | BL486: 28.93 | BM486: 28.08 | BN486: 28.83 | BO486: 30.78 | BP486: 32.13 | BQ486: =((AV486/BF486)^(1/(2010-2000)))-1 -> -0.0049205554 | BR486: =((AM486/AV486)^(1/(2019-2010)))-1 -> -0.011820588
... A626: CAF | B626: Central African Republic | C626: =VLOOKUP(historical_emissions[[#This Row],[Country]],'Liste-Pays'!A:B,2,0) -> AFR | D626: Climate Watch | E626: Total including LUCF | F626: CO2 | G626: MtCO₂e | H626: =I626*(1+$BR626) -> 14.340807 | I626: =J626*(1+$BR626) -> 14.331814 | J626: =K626*(1+$BR626) -> 14.322826 | K626: =L626*(1+$BR626) -> 14.313844 | L626: =M626*(1+$BR626) -> 14.304868 | M626: =N626*(1+$BR626) -> 14.295897 | N626: =O626*(1+$BR626) -> 14.286932 | O626: =P626*(1+$BR626) -> 14.277973 | ... Y626: =Z626*(1+$BR626) -> 14.188686 | Z626: =AA626*(1+$BQ626) -> 14.179789 | AA626: =AB626*(1+$BQ626) -> 14.185798 | AB626: =AC626*(1+$BQ626) -> 14.19181 | AC626: =AD626*(1+$BQ626) -> 14.197825 | AD626: =AE626*(1+$BQ626) -> 14.203843 | AE626: =AF626*(1+$BQ626) -> 14.209862 | AF626: =AG626*(1+$BQ626) -> 14.215885 | AG626: =AH626*(1+$BQ626) -> 14.22191 | ... AI626: =AJ626*(1+$BQ626) -> 14.233967 | AJ626: 14.24 | AK626: 14.22 | AL626: 14.22 | AM626: 14.21 | AN626: 14.19 | AO626: 14.18 | AP626: 14.17 | AQ626: 14.14 | AR626: 14.09 | AS626: 14.08 | AT626: 14.15 | AU626: 14.15 | AV626: 14.13 | AW626: 14.12 | AX626: 14.13 | AY626: 14.19 | AZ626: 14.19 | BA626: 14.17 | BB626: 14.18 | BC626: 14.18 | BD626: 14.2 | BE626: 14.2 | BF626: 14.19 | BG626: 14.19 | BH626: 14.18 | BI626: 14.12 | BJ626: 14.12 | BK626: 14.11 | BL626: 14.11 | BM626: 14.11 | BN626: 14.1 | BO626: 14.09 | BP626: 14.1 | BQ626: =((AV626/BF626)^(1/(2010-2000)))-1 -> -0.00042363969 | BR626: =((AM626/AV626)^(1/(2019-2010)))-1 -> 0.00062750184
A627: NAM | B627: Namibia | C627: =VLOOKUP(historical_emissions[[#This Row],[Country]],'Liste-Pays'!A:B,2,0) -> AFR-EXCLUDED | D627: Climate Watch | E627: Total including LUCF | F627: CO2 | G627: MtCO₂e | H627: =I627*(1+$BR627) -> 18.269324 | I627: =J627*(1+$BR627) -> 18.072161 | J627: =K627*(1+$BR627) -> 17.877125 | K627: =L627*(1+$BR627) -> 17.684195 | L627: =M627*(1+$BR627) -> 17.493347 | M627: =N627*(1+$BR627) -> 17.304558 | N627: =O627*(1+$BR627) -> 17.117807 | O627: =P627*(1+$BR627) -> 16.933071 | ... Y627: =Z627*(1+$BR627) -> 15.19189 | Z627: =AA627*(1+$BQ627) -> 15.027939 | AA627: =AB627*(1+$BQ627) -> 14.947222 | AB627: =AC627*(1+$BQ627) -> 14.866938 | AC627: =AD627*(1+$BQ627) -> 14.787086 | AD627: =AE627*(1+$BQ627) -> 14.707662 | AE627: =AF627*(1+$BQ627) -> 14.628665 | AF627: =AG627*(1+$BQ627) -> 14.550093 | AG627: =AH627*(1+$BQ627) -> 14.471942 | ... AI627: =AJ627*(1+$BQ627) -> 14.316898 | AJ627: 14.24 | AK627: 14.38 | AL627: 14.2 | AM627: 14.51 | AN627: 14.39 | AO627: 14.35 | AP627: 14.35 | AQ627: 14.13 | AR627: 13.76 | AS627: 13.63 | AT627: 13.51 | AU627: 13.34 | AV627: 13.16 | AW627: 13.53 | AX627: 13.44 | AY627: 13.08 | AZ627: 13.03 | BA627: 13.06 | BB627: 12.9 | BC627: 12.81 | BD627: 12.68 | BE627: 13.0 | BF627: 12.47 | BG627: 12.55 | BH627: 12.58 | BI627: 12.54 | BJ627: 12.49 | BK627: 12.34 | BL627: 12.2 | BM627: 11.98 | BN627: 11.79 | BO627: 11.69 | BQ627: =((AV627/BF627)^(1/(2010-2000)))-1 -> 0.0054001451 | BR627: =((AM627/AV627)^(1/(2019-2010)))-1 -> 0.010909764
A628: LBR | B628: Liberia | C628: =VLOOKUP(historical_emissions[[#This Row],[Country]],'Liste-Pays'!A:B,2,0) -> AFR | D628: Climate Watch | E628: Total including LUCF | F628: CO2 | G628: MtCO₂e | H628: =I628*(1+$BR628) -> 15.048203 | I628: =J628*(1+$BR628) -> 15.021249 | J628: =K628*(1+$BR628) -> 14.994343 | K628: =L628*(1+$BR628) -> 14.967486 | L628: =M628*(1+$BR628) -> 14.940676 | M628: =N628*(1+$BR628) -> 14.913915 | N628: =O628*(1+$BR628) -> 14.887201 | O628: =P628*(1+$BR628) -> 14.860536 | ... Y628: =Z628*(1+$BR628) -> 14.596493 | Z628: =AA628*(1+$BQ628) -> 14.570348 | AA628: =AB628*(1+$BQ628) -> 14.534928 | AB628: =AC628*(1+$BQ628) -> 14.499594 | AC628: =AD628*(1+$BQ628) -> 14.464347 | AD628: =AE628*(1+$BQ628) -> 14.429185 | AE628: =AF628*(1+$BQ628) -> 14.394108 | AF628: =AG628*(1+$BQ628) -> 14.359117 | AG628: =AH628*(1+$BQ628) -> 14.32421 | ... AI628: =AJ628*(1+$BQ628) -> 14.254652 | AJ628: 14.22 | AK628: 14.21 | AL628: 14.2 | AM628: 14.37 | AN628: 14.03 | AO628: 14.09 | AP628: 14.07 | AQ628: 14.13 | AR628: 14.16 | AS628: 14.31 | AT628: 14.35 | AU628: 14.26 | AV628: 14.14 | AW628: 13.94 | AX628: 13.95 | AY628: 14.05 | AZ628: 14.1 | BA628: 14.08 | BB628: 13.97 | BC628: 13.88 | BD628: 13.85 | BE628: 13.83 | BF628: 13.8 | BG628: 13.77 | BH628: 13.86 | BI628: 13.82 | BJ628: 13.81 | BK628: 13.79 | BL628: 13.79 | BM628: 13.79 | BN628: 13.78 | BO628: 13.75 | BP628: 13.82 | BQ628: =((AV628/BF628)^(1/(2010-2000)))-1 -> 0.0024368712 | BR628: =((AM628/AV628)^(1/(2019-2010)))-1 -> 0.0017943902
A629: AUS | B629: Australia | C629: =VLOOKUP(historical_emissions[[#This Row],[Country]],'Liste-Pays'!A:B,2,0) -> AUS | D629: Climate Watch | E629: Industrial Processes | F629: F-Gas | G629: MtCO₂e | H629: =I629*(1+$BR629) -> 74.020169 | I629: =J629*(1+$BR629) -> 70.753245 | J629: =K629*(1+$BR629) -> 67.630509 | K629: =L629*(1+$BR629) -> 64.645597 | L629: =M629*(1+$BR629) -> 61.792426 | M629: =N629*(1+$BR629) -> 59.065181 | N629: =O629*(1+$BR629) -> 56.458305 | O629: =P629*(1+$BR629) -> 53.966484 | ... Y629: =Z629*(1+$BR629) -> 34.362683 | Z629: =AA629*(1+$BQ629) -> 32.846066 | AA629: =AB629*(1+$BQ629) -> 30.206084 | AB629: =AC629*(1+$BQ629) -> 27.77829 | AC629: =AD629*(1+$BQ629) -> 25.545627 | AD629: =AE629*(1+$BQ629) -> 23.492414 | AE629: =AF629*(1+$BQ629) -> 21.604226 | AF629: =AG629*(1+$BQ629) -> 19.8678 | AG629: =AH629*(1+$BQ629) -> 18.270939 | ... AI629: =AJ629*(1+$BQ629) -> 15.45194 | AJ629: 14.21 | AK629: 13.55 | AL629: 12.9 | AM629: 12.7 | AN629: 11.8 | AO629: 11.77 | AP629: 11.57 | AQ629: 11.12 | AR629: 10.57 | AS629: 9.84 | AT629: 9.59 | AU629: 9.21 | AV629: 8.46 | AW629: 7.91 | AX629: 7.13 | AY629: 6.66 | AZ629: 6.07 | BA629: 6.76 | BB629: 6.05 | BC629: 5.48 | BD629: 4.98 | BE629: 4.62 | BF629: 3.66 | BG629: 3.24 | BH629: 3.47 | BI629: 2.87 | BJ629: 3.0 | BK629: 3.78 | BL629: 4.52 | BM629: 7.25 | BN629: 7.53 | BO629: 7.7 | BP629: 7.68 | BQ629: =((AV629/BF629)^(1/(2010-2000)))-1 -> 0.087398996 | BR629: =((AM629/AV629)^(1/(2019-2010)))-1 -> 0.046173479
A630: AUS | B630: Australia | C630: =VLOOKUP(historical_emissions[[#This Row],[Country]],'Liste-Pays'!A:B,2,0) -> AUS | D630: Climate Watch | E630: Total including LUCF | F630: F-Gas | G630: MtCO₂e | H630: =I630*(1+$BR630) -> 74.020169 | I630: =J630*(1+$BR630) -> 70.753245 | J630: =K630*(1+$BR630) -> 67.630509 | K630: =L630*(1+$BR630) -> 64.645597 | L630: =M630*(1+$BR630) -> 61.792426 | M630: =N630*(1+$BR630) -> 59.065181 | N630: =O630*(1+$BR630) -> 56.458305 | O630: =P630*(1+$BR630) -> 53.966484 | ... Y630: =Z630*(1+$BR630) -> 34.362683 | Z630: =AA630*(1+$BQ630) -> 32.846066 | AA630: =AB630*(1+$BQ630) -> 30.206084 | AB630: =AC630*(1+$BQ630) -> 27.77829 | AC630: =AD630*(1+$BQ630) -> 25.545627 | AD630: =AE630*(1+$BQ630) -> 23.492414 | AE630: =AF630*(1+$BQ630) -> 21.604226 | AF630: =AG630*(1+$BQ630) -> 19.8678 | AG630: =AH630*(1+$BQ630) -> 18.270939 | ... AI630: =AJ630*(1+$BQ630) -> 15.45194 | AJ630: 14.21 | AK630: 13.55 | AL630: 12.9 | AM630: 12.7 | AN630: 11.8 | AO630: 11.77 | AP630: 11.57 | AQ630: 11.12 | AR630: 10.57 | AS630: 9.84 | AT630: 9.59 | AU630: 9.21 | AV630: 8.46 | AW630: 7.91 | AX630: 7.13 | AY630: 6.66 | AZ630: 6.07 | BA630: 6.76 | BB630: 6.05 | BC630: 5.48 | BD630: 4.98 | BE630: 4.62 | BF630: 3.66 | BG630: 3.24 | BH630: 3.47 | BI630: 2.87 | BJ630: 3.0 | BK630: 3.78 | BL630: 4.52 | BM630: 7.25 | BN630: 7.53 | BO630: 7.7 | BP630: 7.68 | BQ630: =((AV630/BF630)^(1/(2010-2000)))-1 -> 0.087398996 | BR630: =((AM630/AV630)^(1/(2019-2010)))-1 -> 0.046173479
A631: TTO | B631: Trinidad and Tobago | C631: =VLOOKUP(historical_emissions[[#This Row],[Country]],'Liste-Pays'!A:B,2,0) -> CSA | D631: Climate Watch | E631: Energy | F631: CO2 | G631: MtCO₂e | H631: =I631*(1+$BR631) -> 19.1981 | I631: =J631*(1+$BR631) -> 19.672811 | J631: =K631*(1+$BR631) -> 20.159261 | K631: =L631*(1+$BR631) -> 20.657739 | L631: =M631*(1+$BR631) -> 21.168543 | M631: =N631*(1+$BR631) -> 21.691978 | N631: =O631*(1+$BR631) -> 22.228356 | O631: =P631*(1+$BR631) -> 22.777997 | ... Y631: =Z631*(1+$BR631) -> 29.080198 | Z631: =AA631*(1+$BQ631) -> 29.799264 | AA631: =AB631*(1+$BQ631) -> 27.629101 | AB631: =AC631*(1+$BQ631) -> 25.616983 | AC631: =AD631*(1+$BQ631) -> 23.751399 | AD631: =AE631*(1+$BQ631) -> 22.021678 | AE631: =AF631*(1+$BQ631) -> 20.417926 | AF631: =AG631*(1+$BQ631) -> 18.930969 | AG631: =AH631*(1+$BQ631) -> 17.552301 | ... AI631: =AJ631*(1+$BQ631) -> 15.088862 | AJ631: 13.99 | AK631: 13.35 | AL631: 15.23 | AM631: 16.96 | AN631: 17.54 | AO631: 17.99 | AP631: 18.03 | AQ631: 21.02 | AR631: 21.73 | AS631: 21.9 | AT631: 21.25 | AU631: 21.91 | AV631: 21.13 | AW631: 18.68 | AX631: 19.74 | AY631: 20.12 | AZ631: 19.69 | BA631: 17.29 | BB631: 15.86 | BC631: 15.12 | BD631: 12.36 | BE631: 11.32 | BF631: 9.92 | BG631: 9.6 | BH631: 9.63 | BI631: 9.4 | BJ631: 8.92 | BK631: 8.37 | BL631: 8.53 | BM631: 10.43 | BN631: 12.82 | BO631: 12.71 | BP631: 12.84 | BQ631: =((AV631/BF631)^(1/(2010-2000)))-1 -> 0.078546273 | BR631: =((AM631/AV631)^(1/(2019-2010)))-1 -> -0.024130338
A632: ITA | B632: Italy | C632: =VLOOKUP(historical_emissions[[#This Row],[Country]],'Liste-Pays'!A:B,2,0) -> WEU | D632: Climate Watch | E632: Total including LUCF | F632: N2O | G632: MtCO₂e | H632: =I632*(1+$BR632) -> 8.2063084 | I632: =J632*(1+$BR632) -> 8.2351093 | J632: =K632*(1+$BR632) -> 8.2640112 | K632: =L632*(1+$BR632) -> 8.2930145 | L632: =M632*(1+$BR632) -> 8.3221196 | M632: =N632*(1+$BR632) -> 8.3513269 | N632: =O632*(1+$BR632) -> 8.3806367 | O632: =P632*(1+$BR632) -> 8.4100493 | ... Y632: =Z632*(1+$BR632) -> 8.7099134 | Z632: =AA632*(1+$BQ632) -> 8.7404816 | AA632: =AB632*(1+$BQ632) -> 9.1594705 | AB632: =AC632*(1+$BQ632) -> 9.5985443 | AC632: =AD632*(1+$BQ632) -> 10.058666 | AD632: =AE632*(1+$BQ632) -> 10.540844 | AE632: =AF632*(1+$BQ632) -> 11.046136 | AF632: =AG632*(1+$BQ632) -> 11.57565 | AG632: =AH632*(1+$BQ632) -> 12.130547 | ... AI632: =AJ632*(1+$BQ632) -> 13.321417 | AJ632: 13.96 | AK632: 14.11 | AL632: 13.89 | AM632: 14.36 | AN632: 14.45 | AO632: 14.27 | AP632: 14.33 | AQ632: 14.3 | AR632: 14.18 | AS632: 14.53 | AT632: 14.74 | AU632: 14.36 | AV632: 14.82 | AW632: 15.32 | AX632: 16.47 | AY632: 17.79 | AZ632: 18.27 | BA632: 22.73 | BB632: 23.92 | BC632: 22.74 | BD632: 23.29 | BE632: 22.62 | BF632: 23.67 | BG632: 23.38 | BH632: 23.15 | BI632: 22.82 | BJ632: 23.1 | BK632: 22.91 | BL632: 22.26 | BM632: 22.89 | BN632: 23.08 | BO632: 23.58 | BP632: 23.57 | BQ632: =((AV632/BF632)^(1/(2010-2000)))-1 -> -0.045743791 | BR632: =((AM632/AV632)^(1/(2019-2010)))-1 -> -0.0034973208
A633: TZA | B633: Tanzania | C633: =VLOOKUP(historical_emissions[[#This Row],[Country]],'Liste-Pays'!A:B,2,0) -> AFR | D633: Climate Watch | E633: Building | F633: CH4 | G633: MtCO₂e | H633: =I633*(1+$BR633) -> 24.31278 | I633: =J633*(1+$BR633) -> 23.914735 | J633: =K633*(1+$BR633) -> 23.523206 | K633: =L633*(1+$BR633) -> 23.138088 | L633: =M633*(1+$BR633) -> 22.759275 | M633: =N633*(1+$BR633) -> 22.386663 | N633: =O633*(1+$BR633) -> 22.020152 | O633: =P633*(1+$BR633) -> 21.659642 | ... Y633: =Z633*(1+$BR633) -> 18.363725 | Z633: =AA633*(1+$BQ633) -> 18.063077 | AA633: =AB633*(1+$BQ633) -> 17.599797 | AB633: =AC633*(1+$BQ633) -> 17.1484 | AC633: =AD633*(1+$BQ633) -> 16.70858 | AD633: =AE633*(1+$BQ633) -> 16.280041 | AE633: =AF633*(1+$BQ633) -> 15.862492 | AF633: =AG633*(1+$BQ633) -> 15.455653 | AG633: =AH633*(1+$BQ633) -> 15.059249 | ... AI633: =AJ633*(1+$BQ633) -> 14.296679 | AJ633: 13.93 | AK633: 13.8 | AL633: 13.82 | AM633: 13.69 | AN633: 12.96 | AO633: 12.79 | AP633: 12.68 | AQ633: 12.47 | AR633: 12.17 | AS633: 12.33 | AT633: 11.86 | AU633: 12.18 | AV633: 11.8 | AW633: 11.57 | AX633: 11.22 | AY633: 11.05 | AZ633: 11.03 | BA633: 10.71 | BB633: 10.23 | BC633: 10.16 | BD633: 9.75 | BE633: 9.35 | BF633: 9.1 | BG633: 8.62 | BH633: 8.17 | BI633: 7.75 | BJ633: 7.61 | BK633: 7.47 | BL633: 7.33 | BM633: 5.84 | BN633: 5.45 | BO633: 5.28 | BP633: 5.13 | BQ633: =((AV633/BF633)^(1/(2010-2000)))-1 -> 0.026323 | BR633: =((AM633/AV633)^(1/(2019-2010)))-1 -> 0.016644344
A634: KEN | B634: Kenya | C634: =VLOOKUP(historical_emissions[[#This Row],[Country]],'Liste-Pays'!A:B,2,0) -> AFR | D634: Climate Watch | E634: Total including LUCF | F634: CO2 | G634: MtCO₂e | H634: =I634*(1+$BR634) -> 12.557706 | I634: =J634*(1+$BR634) -> 14.010804 | J634: =K634*(1+$BR634) -> 15.632046 | K634: =L634*(1+$BR634) -> 17.440887 | L634: =M634*(1+$BR634) -> 19.459036 | M634: =N634*(1+$BR634) -> 21.710712 | N634: =O634*(1+$BR634) -> 24.222937 | O634: =P634*(1+$BR634) -> 27.025862 | ... Y634: =Z634*(1+$BR634) -> 80.780588 | Z634: =AA634*(1+$BQ634) -> 90.128005 | AA634: =AB634*(1+$BQ634) -> 74.690811 | AB634: =AC634*(1+$BQ634) -> 61.897712 | AC634: =AD634*(1+$BQ634) -> 51.295824 | AD634: =AE634*(1+$BQ634) -> 42.509836 | AE634: =AF634*(1+$BQ634) -> 35.228719 | AF634: =AG634*(1+$BQ634) -> 29.194717 | AG634: =AH634*(1+$BQ634) -> 24.194223 | ... AI634: =AJ634*(1+$BQ634) -> 16.616001 | AJ634: 13.77 | AK634: 13.03 | AL634: 10.09 | AM634: 10.53 | AN634: 10.08 | AO634: 10.45 | AP634: 9.32 | AQ634: 24.06 | AR634: 23.18 | AS634: 21.11 | AT634: 20.07 | AU634: 21.09 | AV634: 28.21 | AW634: 27.4 | AX634: 25.4 | AY634: 24.89 | AZ634: 24.88 | BA634: 23.78 | BB634: 22.86 | BC634: 22.02 | BD634: 22.76 | BE634: 22.99 | BF634: 4.31 | BG634: 3.37 | BH634: 3.15 | BI634: 2.52 | BJ634: 2.89 | BK634: 2.24 | BL634: 1.78 | BM634: 1.66 | BN634: 1.76 | BO634: 1.69 | BP634: 1.94 | BQ634: =((AV634/BF634)^(1/(2010-2000)))-1 -> 0.2066813 | BR634: =((AM634/AV634)^(1/(2019-2010)))-1 -> -0.10371268
A635: PHL | B635: Philippines | C635: =VLOOKUP(historical_emissions[[#This Row],[Country]],'Liste-Pays'!A:B,2,0) -> ODA | D635: Climate Watch | E635: Total including LUCF | F635: N2O | G635: MtCO₂e | H635: =I635*(1+$BR635) -> 20.132195 | I635: =J635*(1+$BR635) -> 19.866658 | J635: =K635*(1+$BR635) -> 19.604623 | K635: =L635*(1+$BR635) -> 19.346044 | L635: =M635*(1+$BR635) -> 19.090876 | M635: =N635*(1+$BR635) -> 18.839074 | N635: =O635*(1+$BR635) -> 18.590593 | O635: =P635*(1+$BR635) -> 18.345389 | ... Y635: =Z635*(1+$BR635) -> 16.064374 | Z635: =AA635*(1+$BQ635) -> 15.85249 | AA635: =AB635*(1+$BQ635) -> 15.617122 | AB635: =AC635*(1+$BQ635) -> 15.385249 | AC635: =AD635*(1+$BQ635) -> 15.156818 | AD635: =AE635*(1+$BQ635) -> 14.931779 | AE635: =AF635*(1+$BQ635) -> 14.710081 | AF635: =AG635*(1+$BQ635) -> 14.491675 | AG635: =AH635*(1+$BQ635) -> 14.276512 | ... AI635: =AJ635*(1+$BQ635) -> 13.855721 | AJ635: 13.65 | AK635: 13.14 | AL635: 13.29 | AM635: 13.14 | AN635: 12.67 | AO635: 13.19 | AP635: 12.21 | AQ635: 11.5 | AR635: 11.75 | AS635: 11.31 | AT635: 10.89 | AU635: 11.09 | AV635: 11.66 | AW635: 10.62 | AX635: 10.31 | AY635: 10.87 | AZ635: 10.44 | BA635: 10.96 | BB635: 11.33 | BC635: 10.81 | BD635: 10.04 | BE635: 10.26 | BF635: 10.04 | BG635: 9.91 | BH635: 9.34 | BI635: 10.21 | BJ635: 9.62 | BK635: 8.84 | BL635: 8.61 | BM635: 8.42 | BN635: 7.98 | BO635: 7.67 | BP635: 8.24 | BQ635: =((AV635/BF635)^(1/(2010-2000)))-1 -> 0.015071148 | BR635: =((AM635/AV635)^(1/(2019-2010)))-1 -> 0.013365962
A636: ISR | B636: Israel | C636: =VLOOKUP(historical_emissions[[#This Row],[Country]],'Liste-Pays'!A:B,2,0) -> MEA | D636: Climate Watch | E636: Industrial Processes | F636: F-Gas | G636: MtCO₂e | H636: =I636*(1+$BR636) -> 45.331036 | I636: =J636*(1+$BR636) -> 43.750111 | J636: =K636*(1+$BR636) -> 42.224322 | K636: =L636*(1+$BR636) -> 40.751744 | L636: =M636*(1+$BR636) -> 39.330523 | M636: =N636*(1+$BR636) -> 37.958868 | N636: =O636*(1+$BR636) -> 36.635048 | O636: =P636*(1+$BR636) -> 35.357397 | ... Y636: =Z636*(1+$BR636) -> 24.792225 | Z636: =AA636*(1+$BQ636) -> 23.927594 | AA636: =AB636*(1+$BQ636) -> 22.613252 | AB636: =AC636*(1+$BQ636) -> 21.371106 | AC636: =AD636*(1+$BQ636) -> 20.197192 | AD636: =AE636*(1+$BQ636) -> 19.087761 | AE636: =AF636*(1+$BQ636) -> 18.03927 | AF636: =AG636*(1+$BQ636) -> 17.048374 | AG636: =AH636*(1+$BQ636) -> 16.111907 | ... AI636: =AJ636*(1+$BQ636) -> 14.390468 | AJ636: 13.6 | AK636: 12.52 | AL636: 11.44 | AM636: 10.97 | AN636: 10.49 | AO636: 10.02 | AP636: 9.54 | AQ636: 9.06 | AR636: 8.85 | AS636: 8.63 | AT636: 8.41 | AU636: 8.19 | AV636: 7.97 | AW636: 7.46 | AX636: 6.96 | AY636: 6.45 | AZ636: 5.94 | BA636: 5.44 | BB636: 5.25 | BC636: 5.07 | BD636: 4.89 | BE636: 4.71 | BF636: 4.53 | BG636: 3.82 | BH636: 3.1 | BI636: 2.39 | BJ636: 1.67 | BK636: 0.96 | BL636: 0.83 | BM636: 0.71 | BN636: 0.58 | BO636: 0.45 | BP636: 0.33 | BQ636: =((AV636/BF636)^(1/(2010-2000)))-1 -> 0.058122652 | BR636: =((AM636/AV636)^(1/(2019-2010)))-1 -> 0.03613532
A637: ISR | B637: Israel | C637: =VLOOKUP(historical_emissions[[#This Row],[Country]],'Liste-Pays'!A:B,2,0) -> MEA | D637: Climate Watch | E637: Total including LUCF | F637: F-Gas | G637: MtCO₂e | H637: =I637*(1+$BR637) -> 45.331036 | I637: =J637*(1+$BR637) -> 43.750111 | J637: =K637*(1+$BR637) -> 42.224322 | K637: =L637*(1+$BR637) -> 40.751744 | L637: =M637*(1+$BR637) -> 39.330523 | M637: =N637*(1+$BR637) -> 37.958868 | N637: =O637*(1+$BR637) -> 36.635048 | O637: =P637*(1+$BR637) -> 35.357397 | ... Y637: =Z637*(1+$BR637) -> 24.792225 | Z637: =AA637*(1+$BQ637) -> 23.927594 | AA637: =AB637*(1+$BQ637) -> 22.613252 | AB637: =AC637*(1+$BQ637) -> 21.371106 | AC637: =AD637*(1+$BQ637) -> 20.197192 | AD637: =AE637*(1+$BQ637) -> 19.087761 | AE637: =AF637*(1+$BQ637) -> 18.03927 | AF637: =AG637*(1+$BQ637) -> 17.048374 | AG637: =AH637*(1+$BQ637) -> 16.111907 | ... AI637: =AJ637*(1+$BQ637) -> 14.390468 | AJ637: 13.6 | AK637: 12.52 | AL637: 11.44 | AM637: 10.97 | AN637: 10.49 | AO637: 10.02 | AP637: 9.54 | AQ637: 9.06 | AR637: 8.85 | AS637: 8.63 | AT637: 8.41 | AU637: 8.19 | AV637: 7.97 | AW637: 7.46 | AX637: 6.96 | AY637: 6.45 | AZ637: 5.94 | BA637: 5.44 | BB637: 5.25 | BC637: 5.07 | BD637: 4.89 | BE637: 4.71 | BF637: 4.53 | BG637: 3.82 | BH637: 3.1 | BI637: 2.39 | BJ637: 1.67 | BK637: 0.96 | BL637: 0.83 | BM637: 0.71 | BN637: 0.58 | BO637: 0.45 | BP637: 0.33 | BQ637: =((AV637/BF637)^(1/(2010-2000)))-1 -> 0.058122652 | BR637: =((AM637/AV637)^(1/(2019-2010)))-1 -> 0.03613532
A638: CHL | B638: Chile | C638: =VLOOKUP(historical_emissions[[#This Row],[Country]],'Liste-Pays'!A:B,2,0) -> CSA | D638: Climate Watch | E638: Total including LUCF | F638: CH4 | G638: MtCO₂e | H638: =I638*(1+$BR638) -> 16.419097 | I638: =J638*(1+$BR638) -> 16.252012 | J638: =K638*(1+$BR638) -> 16.086628 | K638: =L638*(1+$BR638) -> 15.922926 | L638: =M638*(1+$BR638) -> 15.76089 | M638: =N638*(1+$BR638) -> 15.600504 | N638: =O638*(1+$BR638) -> 15.441749 | O638: =P638*(1+$BR638) -> 15.28461 | ... Y638: =Z638*(1+$BR638) -> 13.798538 | Z638: =AA638*(1+$BQ638) -> 13.65812 | AA638: =AB638*(1+$BQ638) -> 13.651293 | AB638: =AC638*(1+$BQ638) -> 13.644469 | AC638: =AD638*(1+$BQ638) -> 13.637648 | AD638: =AE638*(1+$BQ638) -> 13.630831 | AE638: =AF638*(1+$BQ638) -> 13.624018 | AF638: =AG638*(1+$BQ638) -> 13.617207 | AG638: =AH638*(1+$BQ638) -> 13.6104 | ... AI638: =AJ638*(1+$BQ638) -> 13.596797 | AJ638: 13.59 | AK638: 13.33 | AL638: 13.48 | AM638: 13.19 | AN638: 12.65 | AO638: 12.64 | AP638: 11.34 | AQ638: 11.2 | AR638: 11.17 | AS638: 11.86 | AT638: 12.88 | AU638: 12.35 | AV638: 12.03 | AW638: 12.08 | AX638: 12.11 | AY638: 12.14 | AZ638: 12.56 | BA638: 12.59 | BB638: 12.55 | BC638: 12.27 | BD638: 12.18 | BE638: 12.05 | BF638: 11.97 | BG638: 12.09 | BH638: 11.93 | BI638: 11.72 | BJ638: 11.19 | BK638: 10.93 | BL638: 10.63 | BM638: 10.19 | BN638: 9.85 | BO638: 9.53 | BP638: 9.36 | BQ638: =((AV638/BF638)^(1/(2010-2000)))-1 -> 0.00050012606 | BR638: =((AM638/AV638)^(1/(2019-2010)))-1 -> 0.010280871
...

Sheet Liste-Pays
A1: Country or Area | B1: Region TIAM | E1: pas andorra
A2: Andorra | B2: WEU | E2: tuvalu
A3: Afghanistan | B3: ODA | E3: sudan==south sudan
A4: Albania | B4: EEU | E4: coree (democratic ou republic) | G4: oda nord
A5: Algeria | B5: AFR | E5: macedonia==north macedonia?
A6: Angola | B6: AFR
A7: Anguilla | B7: CSA
A8: Antigua and Barbuda | B8: CSA
A9: Argentina | B9: CSA
A10: Armenia | B10: FSU
A11: Aruba | B11: CSA-EXCLUDED
A12: Australia | B12: AUS
A13: Austria | B13: WEU | E13: changement UE
A14: Azerbaijan | B14: FSU
A15: Bahamas | B15: CSA
A16: Bahrain | B16: MEA
A17: Bangladesh | B17: ODA
A18: Barbados | B18: CSA
A19: Belarus | B19: FSU
A20: Belgium | B20: WEU
A21: Belize | B21: CSA
A22: Benin | B22: AFR
A23: Bermuda | B23: CSA
A24: Bhutan | B24: ODA
A25: Bolivia | B25: CSA
... A67: Ethiopia | B67: AFR
A68: Faeroe Islands
A69: Falkland Islands (Malvinas) | B69: CSA-EXCLUDED
A70: Fiji | B70: ODA
A71: Finland | B71: WEU
A72: France | B72: WEU
A73: French Guiana | B73: CSA
A74: French Polynesia | B74: ODA
A75: Gabon | B75: AFR
A76: Gambia | B76: AFR
A77: Georgia | B77: FSU
A78: Germany | B78: WEU
A79: Ghana | B79: AFR
A80: Gibraltar | B80: WEU
... A149: Norway | B149: WEU
...

Sheet proj 1,5
